<?xml version="1.0"?>
<robot name="seekurjr" 

       xmlns:xi="http://www.w3.org/2001/XInclude"
       xmlns:gazebo="http://playerstage.sourceforge.net/gazebo/xmlschema/#gz"
       xmlns:model="http://playerstage.sourceforge.net/gazebo/xmlschema/#model"
       xmlns:sensor="http://playerstage.sourceforge.net/gazebo/xmlschema/#sensor"
       xmlns:body="http://playerstage.sourceforge.net/gazebo/xmlschema/#body"
       xmlns:geom="http://playerstage.sourceforge.net/gazebo/xmlschema/#geom"
       xmlns:joint="http://playerstage.sourceforge.net/gazebo/xmlschema/#joint"
       xmlns:interface="http://playerstage.sourceforge.net/gazebo/xmlschema/#interface"
       xmlns:rendering="http://playerstage.sourceforge.net/gazebo/xmlschema/#rendering"
       xmlns:renderable="http://playerstage.sourceforge.net/gazebo/xmlschema/#renderable"
       xmlns:controller="http://playerstage.sourceforge.net/gazebo/xmlschema/#controller"
       xmlns:physics="http://playerstage.sourceforge.net/gazebo/xmlschema/#physics">

  <!-- BASE FOOTPRINT -->
  <!-- base_footprint is a fictitious link(frame) that is on the ground right below base_link origin,navigation stack depends on this frame -->


  <!-- BASE_LINK (RED) -->
  <link name="base_link">

    <inertial>
      <mass value="70.0" />
      <origin xyz="0 0 0" rpy="1.570796 0 1.570796"/>
      <inertia  ixx="0.011083" ixy="-0.000132"  ixz="-0.000303"  iyy="0.011182"  iyz="-0.000597"  izz="0.005307" />
    </inertial>

    <visual>
       <origin xyz="0 0 0" rpy="1.570796 0 1.570796" />
       <geometry>
	 <mesh filename="package://seekurjr_gazebo/meshes/seekurjr_body_new_low2.dae" scale="1 1 1"/>
       </geometry>
    </visual>

    <collision>
       <origin xyz="0 0 0" rpy="1.570796 0 1.570796" />
       <geometry>
         <mesh filename="package://seekurjr_gazebo/meshes/seekurjr_body_new_low2.stl" scale="1 1 1"/>
       </geometry>
    </collision>     


  </link>

<!--
  <gazebo reference="base_link">
    <material>Gazebo/Blue</material>
    <turnGravityOff>false</turnGravityOff>
  </gazebo>
 -->
 
<!-- LASER -->

  <link name="lms1xx_link">
    <collision>
      <origin xyz="0 0 0" rpy="0 0 0"/>
      <geometry>
         <box size="0.1 0.1 0.1"/>
      </geometry>
    </collision>

    <visual>
      <origin xyz="0 0 0" rpy="0 0 0"/>
      <geometry>
           <mesh filename="package://seekurjr_gazebo/meshes/lms100.dae" scale="2 2 2" />
      </geometry>
    </visual>

    <inertial>
      <mass value="1e-5" />
      <origin xyz="0 0 0" rpy="0 0 0"/>
      <inertia ixx="1e-6" ixy="0" ixz="0" iyy="1e-6" iyz="0" izz="1e-6" />
    </inertial>
  </link>
 
 <joint name="lms1xx_joint" type="fixed">
    <axis xyz="1 0 0" />
    <origin xyz="0.52 0.0 0.24" rpy="0 0 0"/>
    <parent link="base_link"/>
    <child link="lms1xx_link"/>
  </joint>

  <gazebo reference="lms1xx_link">
    <sensor type="ray" name="laser">
      <pose>0 0 0 0 0 0</pose>
      <visualize>true</visualize>
      <update_rate>40</update_rate>
      <ray>
        <scan>
          <horizontal>
            <samples>720</samples>
            <resolution>1</resolution>
            <min_angle>-2.26889</min_angle>
            <max_angle>2.2689</max_angle>
          </horizontal>
        </scan>
        <range>
          <min>0.10</min>
          <max>30.0</max>
          <resolution>0.01</resolution>
        </range>
        <noise>
          <type>gaussian</type>-->
          <!-- Noise parameters based on published spec for Hokuyo laser
               achieving "+-30mm" accuracy at range < 10m.  A mean of 0.0m and
               stddev of 0.01m will put 99.7% of samples within 0.03m of the true reading. -->
          <mean>0.0</mean>
          <stddev>0.01</stddev>
        </noise>
      </ray>
      </sensor>
  </gazebo>


<link name="imu_link">
  <inertial>
    <mass value="0.001"/>
    <origin rpy="0 0 0" xyz="0 0 0"/>
    <inertia ixx="0.0001" ixy="0" ixz="0" iyy="0.000001" iyz="0" izz="0.0001"/>
  </inertial>
  <visual>
    <origin rpy="0 0 0" xyz="0 0 0"/>
    <geometry>
      <box size="0.1 0.1 0.1"/>
    </geometry>
  </visual>
  <collision>
    <origin rpy="0 0 0" xyz="0 0 0"/>
    <geometry>
      <box size=".001 .001 .001"/>
    </geometry>
  </collision>
</link>

<joint name="imu_joint" type="fixed">
	<axis xyz="1 0 0"/> <!-- 0 1 0 -->
	<origin xyz="0 0 0.19"/>
	<parent link="base_link"/>
	<child link="imu_link"/>
</joint>


  <gazebo reference="imu_link">
    
    
    <sensor name="imu_sensor" type="imu">
      <always_on>1</always_on>
      <update_rate>1000.0</update_rate>
      <imu>
        <noise>
          <type>gaussian</type>
          
          <rate>
            <mean>0.0</mean>
            <stddev>2e-4</stddev>
            <bias_mean>0.0000075</bias_mean>
            <bias_stddev>0.0000008</bias_stddev>
          </rate>
          <accel>
            <mean>0.0</mean>
            <stddev>1.7e-2</stddev>
            <bias_mean>0.1</bias_mean>
            <bias_stddev>0.001</bias_stddev>
          </accel>
        </noise>
      </imu>
    </sensor>
  </gazebo>


  <joint name="camera_joint" type="fixed">
    <axis xyz="1 0 0"/> <!-- 0 1 0 -->
    <origin xyz="0.42 0 0.41" rpy="0 0 0"/>
    <parent link="base_link"/>
    <child link="camera_link"/>
  </joint>

    <link name="camera_link">
      <inertial>
        <mass value="0.001" />
        <origin xyz="0 0 0" rpy="0 0 0" />
        <inertia ixx="0.0001" ixy="0" ixz="0" iyy="0.0001" iyz="0" izz="0.0001" />
      </inertial>
      <visual>
        <origin xyz="0 0 0" rpy="0 0 0" />
        <geometry>
          <box size="0.04 0.16 0.04" />
        </geometry>
        <material name="Yellow">
          <color rgba="0.0 0.0 0.8 1"/>
        </material>
      </visual>
      <collision>
        <origin xyz="0 0 0" rpy="0 0 0" />
        <geometry>
          <box size="0.04 0.16 0.04" />
        </geometry>
      </collision>
    </link>

    
    <joint name="camera_optical_joint" type="fixed">
      <origin xyz="0 0 0" rpy="-1.570796 0.0 -1.570796" />
      <parent link="camera_link" />
      <child link="camera_optical_frame"/>
    </joint>
  
    <link name="camera_optical_frame"/>
    
    <gazebo reference="camera_link">
      <sensor type="camera" name="camera_camera_sensor">
        <update_rate>15</update_rate>
        <camera>
          <horizontal_fov angle='1.57079633'/>
          <image>
            <format>R8G8B8</format>
            <width>320</width>
            <height>240</height>
          </image>
          <clip>
            <near>0.01</near>
            <far>100</far>
          </clip>
        </camera>

        <plugin name="camera_camera_controller" filename="libgazebo_ros_camera.so">
          <cameraName>camera</cameraName>
          <alwaysOn>true</alwaysOn>
          <updateRate>15</updateRate>
          <imageTopicName>left/image_raw</imageTopicName>
          <cameraInfoTopicName>left/camera_info</cameraInfoTopicName>
          <frameName>camera_optical_frame</frameName>
        </plugin>
      </sensor>
    </gazebo>

<!-- WHEELS -->

<link name="bl_wheel">
      <visual>
        <origin xyz="0 0 0" rpy="0 0 0"/>
        <geometry>
				<mesh filename="package://seekurjr_gazebo/meshes/seekurjr_left_side_wheel_low2.stl" scale="1 1 1"/>
        </geometry>
        <material name="WheelBlack">
					<color rgba="0.117 0.117 0.117 1"/>
        </material>
      </visual>
      <collision>
       <origin xyz="0 0 0" rpy="0 0 0"/>
       <geometry>
         <mesh filename="package://seekurjr_gazebo/meshes/seekurjr_left_side_wheel_low2.stl" scale="1 1 1"/>
       </geometry>
      </collision>   
    <inertial>
      <mass value="1.75" />
      <origin xyz="0 0 0" rpy="0 0 0"/>
      <inertia ixx="0.000195" ixy="0" ixz="0" iyy="0.000327" iyz="0" izz="0.000195" />
    </inertial>
</link>

<joint name="bl_wheel_joint" type="revolute">
<origin xyz="-0.215 0.32 0.083" rpy="0 0 0"/>
<parent link="base_link"/>
<child link="bl_wheel"/>
<axis xyz="0 1 0"/>>
<limit effort="30" velocity="1.0"  lower="-100" upper="100" />
</joint>

<link name="fl_wheel">
      <visual>
        <origin xyz="0 0 0" rpy="0 0 0"/>
        <geometry>
				<mesh filename="package://seekurjr_gazebo/meshes/seekurjr_left_side_wheel_low2.stl" scale="1 1 1"/>
        </geometry>
        <material name="WheelBlack">
					<color rgba="0.117 0.117 0.117 1"/>
        </material>
      </visual>
      <collision>
       <origin xyz="0 0 0" rpy="0 0 0"/>
       <geometry>
         <mesh filename="package://seekurjr_gazebo/meshes/seekurjr_left_side_wheel_low2.stl" scale="1 1 1"/>
       </geometry>
      </collision>
    <inertial>
      <mass value="1.75" />
      <origin xyz="0 0 0" rpy="0 0 0"/>
      <inertia ixx="0.000195" ixy="0" ixz="0" iyy="0.000327" iyz="0" izz="0.000195" />
    </inertial>
</link>

<joint name="fl_wheel_joint" type="revolute">
<origin xyz="0.215 0.32 0.083" rpy="0 0 0"/>
<parent link="base_link"/>
<child link="fl_wheel"/>
<axis xyz="0 1 0"/>>
<limit effort="30" velocity="1.0"  lower="-100" upper="100" />
</joint>

<link name="br_wheel">
      <visual>
        <origin xyz="0 0 0" rpy="0 0 0"/>
        <geometry>
				<mesh filename="package://seekurjr_gazebo/meshes/seekurjr_right_side_wheel_low2.stl" scale="1 1 1"/>
        </geometry>
        <material name="WheelBlack">
					<color rgba="0.117 0.117 0.117 1"/>
        </material>
      </visual>
      <collision>
       <origin xyz="0 0 0" rpy="0 0 0"/>
       <geometry>
         <mesh filename="package://seekurjr_gazebo/meshes/seekurjr_right_side_wheel_low2.stl" scale="1 1 1"/>
       </geometry>
      </collision>
    <inertial>
      <mass value="1.75" />
      <origin xyz="0 0 0" rpy="0 0 0"/>
      <inertia ixx="0.000195" ixy="0" ixz="0" iyy="0.000327" iyz="0" izz="0.000195" />
    </inertial>
</link>

<joint name="br_wheel_joint" type="revolute">
<origin xyz="-0.215 -0.32 0.083" rpy="0 0 0"/>
<parent link="base_link"/>
<child link="br_wheel"/>
<axis xyz="0 1 0"/>>
<limit effort="30" velocity="1.0"  lower="-100" upper="100" />
</joint>

<link name="fr_wheel">
      <visual>
        <origin xyz="0 0 0" rpy="0 0 0"/>
        <geometry>
				<mesh filename="package://seekurjr_gazebo/meshes/seekurjr_right_side_wheel_low2.stl" scale="1 1 1"/>
        </geometry>
        <material name="WheelBlack">
					<color rgba="0.117 0.117 0.117 1"/>
        </material>
      </visual>
      <collision>
       <origin xyz="0 0 0" rpy="0 0 0"/>
       <geometry>
         <mesh filename="package://seekurjr_gazebo/meshes/seekurjr_right_side_wheel_low2.stl" scale="1 1 1"/>
       </geometry>
      </collision> 
    <inertial>
      <mass value="1.75" />
      <origin xyz="0 0 0" rpy="0 0 0"/>
      <inertia ixx="0.000195" ixy="0" ixz="0" iyy="0.000327" iyz="0" izz="0.000195" />
    </inertial>
</link>

<joint name="fr_wheel_joint" type="revolute">
<origin xyz="0.215 -0.32 0.083" rpy="0 0 0"/>
<parent link="base_link"/>
<child link="fr_wheel"/>
<axis xyz="0 1 0"/>>
<limit effort="30" velocity="1.0"  lower="-100" upper="100" />
</joint>

          <gazebo reference="fr_wheel">
            <mu1>0.2</mu1>
            <mu2>0.2</mu2>
            <material>Gazebo/Grey</material>
          </gazebo>

          <gazebo reference="br_wheel">
            <mu1>0.2</mu1>
            <mu2>0.2</mu2>
            <material>Gazebo/Grey</material>
          </gazebo>

          <gazebo reference="fl_wheel">
            <mu1>0.2</mu1>
            <mu2>0.2</mu2>
            <material>Gazebo/Grey</material>
          </gazebo>

          <gazebo reference="bl_wheel">
            <mu1>0.2</mu1>
            <mu2>0.2</mu2>
            <material>Gazebo/Grey</material>
          </gazebo>

</robot>




