<?xml version="1.0" ?>
<!-- =================================================================================== -->
<!-- |    This document was autogenerated by xacro from seekurjr.xacro.xml             | -->
<!-- |    EDITING THIS FILE BY HAND IS NOT RECOMMENDED                                 | -->
<!-- =================================================================================== -->
<robot name="seekurjr" xmlns:xacro="http://www.ros.org/wiki/xacro">
  <!-- define global properties -->
  <!-- <property name="wheel_separation" value="0.66357" /> -->
  <!--
SeekurJr Base

m=77; h=0.5; w=0.84; d=1.05; 

length of the robot with laser rangefinder, etc 1.05m
width of the robot with wheels, etc 0.84m
height of the robot with all stuff 0.5m

-->
  <!--
  <xacro:include filename="$(find seekurjr_gazebo)/urdf/base.urdf.xml" />
  -->
  <link name="base_footprint">
    <!--
[ WARN] The root link base_footprint has an inertia specified in the URDF, but KDL does not support a root link with an inertia.  As a workaround, you can add an extra dummy link to your URDF.
-->
    <inertial>
      <mass value="0.0001"/>
      <origin xyz="0 0 0"/>
      <inertia ixx="0.0001" ixy="0.0" ixz="0.0" iyy="0.0001" iyz="0.0" izz="0.0001"/>
    </inertial>
    <visual>
      <origin rpy="0 0 0" xyz="0 0 0"/>
      <geometry>
        <box size="0.001 0.001 0.001"/>
      </geometry>
      <material name="Green">
        <color rgba="0 0.8 0 1"/>
      </material>
    </visual>
    <!-- 
	<collision>
		<origin xyz="0 0 ${base_size_z/2 + ground_clearance}" rpy="0 0 0" />
		<geometry>
			<box size="0.001 0.001 0.001" />
		</geometry>
	</collision>-->
  </link>
  <joint name="base_footprint_joint" type="fixed">
    <!-- NB: While you would think this would make it go up, it is oddly reversed.
		This moves the joint to 0,0,0 where we want it for rviz, etc. 
		origin xyz="0 0 ${base_size_z/2 + 0.051}" rpy="0 0 0"-->
    <origin rpy="0 0 0" xyz="0 0 0"/>
    <parent link="base_footprint"/>
    <child link="base_link"/>
  </joint>
  <link name="base_link">
    <inertial>
      <mass value="70.0"/>
      <origin rpy="0 0 0" xyz="0 0 0.2"/>
      <inertia ixx="3.03333212" ixy="0.0" ixz="0.0" iyy="7.3645803875" iyz="0.0" izz="8.5312465875"/>
    </inertial>
    <visual>
      <origin rpy="0 0 0" xyz="0 0 0.2"/>
      <geometry>
        <box size="1.05 0.4371 0.3"/>
      </geometry>
    </visual>
    <collision>
      <origin rpy="0 0 0" xyz="0 0 0.2"/>
      <geometry>
        <box size="1.05 0.6 0.4"/>
      </geometry>
    </collision>
  </link>
  <link name="bl_wheel">
    <visual>
      <origin rpy="1.57079632679 0 0" xyz="0 0 0"/>
      <geometry>
        <cylinder length="0.164" radius="0.19"/>
      </geometry>
      <material name="WheelBlack">
        <color rgba="0.117 0.117 0.117 1"/>
      </material>
    </visual>
    <collision>
      <origin rpy="1.57079632679 0 0" xyz="0 0 0"/>
      <geometry>
        <cylinder length="0.164" radius="0.19"/>
      </geometry>
    </collision>
    <inertial>
      <mass value="1.75"/>
      <origin rpy="0 0 0" xyz="0 0 0"/>
      <inertia ixx="0.0197160754469" ixy="0.0" ixz="0.0" iyy="0.0197160754469" iyz="0.0" izz="0.0315875"/>
    </inertial>
  </link>
  <link name="fl_wheel">
    <visual>
      <origin rpy="1.57079632679 0 0" xyz="0 0 0"/>
      <geometry>
        <cylinder length="0.164" radius="0.19"/>
      </geometry>
      <material name="WheelBlack">
        <color rgba="0.117 0.117 0.117 1"/>
      </material>
    </visual>
    <collision>
      <origin rpy="1.57079632679 0 0" xyz="0 0 0"/>
      <geometry>
        <cylinder length="0.164" radius="0.19"/>
      </geometry>
    </collision>
    <inertial>
      <mass value="1.75"/>
      <origin rpy="0 0 0" xyz="0 0 0"/>
      <inertia ixx="0.0197160754469" ixy="0.0" ixz="0.0" iyy="0.0197160754469" iyz="0.0" izz="0.0315875"/>
    </inertial>
  </link>
  <link name="br_wheel">
    <visual>
      <origin rpy="1.57079632679 0 0" xyz="0 0 0"/>
      <geometry>
        <cylinder length="0.164" radius="0.19"/>
      </geometry>
      <material name="WheelBlack">
        <color rgba="0.117 0.117 0.117 1"/>
      </material>
    </visual>
    <collision>
      <origin rpy="1.57079632679 0 0" xyz="0 0 0"/>
      <geometry>
        <cylinder length="0.164" radius="0.19"/>
      </geometry>
    </collision>
    <inertial>
      <mass value="1.75"/>
      <origin rpy="0 0 0" xyz="0 0 0"/>
      <inertia ixx="0.0197160754469" ixy="0.0" ixz="0.0" iyy="0.0197160754469" iyz="0.0" izz="0.0315875"/>
    </inertial>
  </link>
  <link name="fr_wheel">
    <visual>
      <origin rpy="1.57079632679 0 0" xyz="0 0 0"/>
      <geometry>
        <cylinder length="0.164" radius="0.19"/>
      </geometry>
      <material name="WheelBlack">
        <color rgba="0.117 0.117 0.117 1"/>
      </material>
    </visual>
    <collision>
      <origin rpy="1.57079632679 0 0" xyz="0 0 0"/>
      <geometry>
        <cylinder length="0.164" radius="0.19"/>
      </geometry>
    </collision>
    <inertial>
      <mass value="1.75"/>
      <origin rpy="0 0 0" xyz="0 0 0"/>
      <inertia ixx="0.0197160754469" ixy="0.0" ixz="0.0" iyy="0.0197160754469" iyz="0.0" izz="0.0315875"/>
    </inertial>
  </link>
  <joint name="bl_wheel_joint" type="continuous">
    <origin rpy="0 0 0" xyz="-0.215 0.32 0.083"/>
    <parent link="base_link"/>
    <child link="bl_wheel"/>
    <axis xyz="0 1 0"/>
    <dynamics damping="1.0" friction="0.0"/>
    <limit effort="30" lower="-100" upper="100" velocity="1.0"/>
  </joint>
  <joint name="fl_wheel_joint" type="continuous">
    <origin rpy="0 0 0" xyz="0.215 0.32 0.083"/>
    <parent link="base_link"/>
    <child link="fl_wheel"/>
    <axis xyz="0 1 0"/>
    <dynamics damping="1.0" friction="0.0"/>
    <limit effort="30" lower="-100" upper="100" velocity="1.0"/>
  </joint>
  <joint name="br_wheel_joint" type="continuous">
    <origin rpy="0 0 0" xyz="-0.215 -0.32 0.083"/>
    <parent link="base_link"/>
    <child link="br_wheel"/>
    <axis xyz="0 1 0"/>
    <dynamics damping="1.0" friction="0.0"/>
    <limit effort="30" lower="-100" upper="100" velocity="1.0"/>
  </joint>
  <joint name="fr_wheel_joint" type="continuous">
    <origin rpy="0 0 0" xyz="0.215 -0.32 0.083"/>
    <parent link="base_link"/>
    <child link="fr_wheel"/>
    <axis xyz="0 1 0"/>
    <dynamics damping="1.0" friction="0.0"/>
    <limit effort="30" lower="-100" upper="100" velocity="1.0"/>
  </joint>
  <gazebo reference="fr_wheel">
    <!-- kp and kd for rubber -->
    <kp>1000000.0</kp>
    <kd>100.0</kd>
    <mu1>0.9</mu1>
    <mu2>0.9</mu2>
    <fdir1>0 1 0</fdir1>
    <maxVel>1.0</maxVel>
    <minDepth>0.00</minDepth>
    <material>Gazebo/Grey</material>
  </gazebo>
  <gazebo reference="br_wheel">
    <!-- kp and kd for rubber -->
    <kp>1000000.0</kp>
    <kd>100.0</kd>
    <mu1>0.9</mu1>
    <mu2>0.9</mu2>
    <fdir1>0 1 0</fdir1>
    <maxVel>1.0</maxVel>
    <minDepth>0.00</minDepth>
    <material>Gazebo/Grey</material>
  </gazebo>
  <gazebo reference="fl_wheel">
    <!-- kp and kd for rubber -->
    <kp>1000000.0</kp>
    <kd>100.0</kd>
    <mu1>0.9</mu1>
    <mu2>0.9</mu2>
    <fdir1>0 1 0</fdir1>
    <maxVel>1.0</maxVel>
    <minDepth>0.00</minDepth>
    <material>Gazebo/Grey</material>
  </gazebo>
  <gazebo reference="bl_wheel">
    <!-- kp and kd for rubber -->
    <kp>1000000.0</kp>
    <kd>100.0</kd>
    <mu1>0.9</mu1>
    <mu2>0.9</mu2>
    <fdir1>0 1 0</fdir1>
    <maxVel>1.0</maxVel>
    <minDepth>0.00</minDepth>
    <material>Gazebo/Grey</material>
  </gazebo>
  <gazebo>
    <plugin filename="libgazebo_ros_skid_steer_drive.so" name="skid_steer_drive_controller">
      <updateRate>100.0</updateRate>
      <robotNamespace>/seekurjr</robotNamespace>
      <leftFrontJoint>fl_wheel_joint</leftFrontJoint>
      <rightFrontJoint>fr_wheel_joint</rightFrontJoint>
      <leftRearJoint>bl_wheel_joint</leftRearJoint>
      <rightRearJoint>br_wheel_joint</rightRearJoint>
      <wheelSeparation>0.66</wheelSeparation>
      <wheelDiameter>0.385</wheelDiameter>
      <robotBaseFrame>base_link</robotBaseFrame>
      <torque>50</torque>
      <topicName>cmd_vel</topicName>
      <commandTopic>cmd_vel</commandTopic>
      <odometryTopic>odom_raw</odometryTopic>
      <odometryFrame>odom</odometryFrame>
      <!--
    <broadcastTF>false</broadcastTF>
    -->
      <max_force>50.0</max_force>
    </plugin>
  </gazebo>
  <gazebo>
    <plugin filename="libgazebo_ros_p3d.so" name="gazebo_ros_p3d">
      <bodyName>base_link</bodyName>
      <topicName>/ground_truth/state</topicName>
      <alwaysOn>true</alwaysOn>
      <updateRate>100.0</updateRate>
    </plugin>
  </gazebo>
  <gazebo>
    <plugin filename="libgazebo_ros_control.so" name="ros_control">
      <robotNamespace>/seekurjr</robotNamespace>
    </plugin>
  </gazebo>
  <link name="lms1xx_link">
    <collision>
      <origin rpy="0 0 0" xyz="0 0 0"/>
      <geometry>
        <box size="0.1 0.1 0.1"/>
      </geometry>
    </collision>
    <visual>
      <origin rpy="0 0 0" xyz="0 0 0"/>
      <geometry>
        <mesh filename="package://seekurjr_gazebo/meshes/lms100.dae" scale="2 2 2"/>
      </geometry>
    </visual>
    <inertial>
      <mass value="1e-5"/>
      <origin rpy="0 0 0" xyz="0 0 0"/>
      <inertia ixx="1e-6" ixy="0" ixz="0" iyy="1e-6" iyz="0" izz="1e-6"/>
    </inertial>
  </link>
  <joint name="lms1xx_joint" type="fixed">
    <axis xyz="1 0 0"/>
    <origin rpy="0 0 0" xyz="0.52 0.0 0.24"/>
    <parent link="base_link"/>
    <child link="lms1xx_link"/>
  </joint>
  <gazebo reference="lms1xx_link">
    <sensor name="lms1xx" type="ray">
      <pose>0 0 0 0 0 0</pose>
      <visualize>true</visualize>
      <update_rate>20</update_rate>
      <ray>
        <scan>
          <horizontal>
            <samples>720</samples>
            <resolution>1</resolution>
            <min_angle>-2.35619449</min_angle>
            <max_angle>2.35619449</max_angle>
          </horizontal>
        </scan>
        <range>
          <min>0.50</min>
          <max>20.0</max>
          <resolution>0.01</resolution>
        </range>
        <noise>
          <!--
				<type> none </type>
				-->
          <!-- Noise parameters based on published spec for Hokuyo laser
             achieving "+-30mm" accuracy at range < 10m. A mean of 0.0m and
             stddev of 0.01m will put 99.7% of samples within 0.03m of the true
             reading. -->
          <type>gaussian</type>
          <mean>0.0</mean>
          <stddev>0.01</stddev>
        </noise>
      </ray>
      <plugin filename="libgazebo_ros_laser.so" name="gazebo_ros_lms1xx_controller">
        <topicName>/seekurjr/lms1xx/scan</topicName>
        <frameName>lms1xx_link</frameName>
      </plugin>
    </sensor>
  </gazebo>
  <link name="camera_link">
    <inertial>
      <mass value="0.001"/>
      <origin rpy="0 0 0" xyz="0 0 0"/>
      <inertia ixx="0.0001" ixy="0" ixz="0" iyy="0.0001" iyz="0" izz="0.0001"/>
    </inertial>
    <visual>
      <origin rpy="0 0 0" xyz="0 0 0"/>
      <geometry>
        <box size="0.04 0.16 0.04"/>
      </geometry>
      <material name="Yellow">
        <color rgba="0.0 0.0 0.8 1"/>
      </material>
    </visual>
    <collision>
      <origin rpy="0 0 0" xyz="0 0 0"/>
      <geometry>
        <box size="0.04 0.16 0.04"/>
      </geometry>
    </collision>
  </link>
  <link name="left_camera_optical_frame"/>
  <joint name="camera_optical_joint" type="fixed">
    <origin rpy="-1.570796 0.0 -1.570796" xyz="0 0 0"/>
    <parent link="camera_link"/>
    <child link="left_camera_optical_frame"/>
  </joint>
  <joint name="camera_joint" type="fixed">
    <axis xyz="1 0 0"/>
    <!-- 0 1 0 -->
    <origin rpy="0 0 0" xyz="0.42 0 0.41"/>
    <parent link="base_link"/>
    <child link="camera_link"/>
  </joint>
  <gazebo reference="camera_link">
    <sensor name="stereo_camera" type="multicamera">
      <update_rate>30.0</update_rate>
      <visualize>true</visualize>
      <camera name="left">
        <horizontal_fov>1.3962634</horizontal_fov>
        <image>
          <width>752</width>
          <height>480</height>
          <format>R8G8B8</format>
        </image>
        <clip>
          <near>0.02</near>
          <far>300</far>
        </clip>
        <noise>
          <type>gaussian</type>
          <mean>0.0</mean>
          <stddev>0.007</stddev>
        </noise>
      </camera>
      <camera name="right">
        <pose>0 -0.07 0 0 0 0</pose>
        <horizontal_fov>1.3962634</horizontal_fov>
        <image>
          <width>752</width>
          <height>480</height>
          <format>R8G8B8</format>
        </image>
        <clip>
          <near>0.02</near>
          <far>300</far>
        </clip>
        <noise>
          <type>gaussian</type>
          <mean>0.0</mean>
          <stddev>0.007</stddev>
        </noise>
      </camera>
      <plugin filename="libgazebo_ros_multicamera.so" name="stereo_camera_controller">
        <alwaysOn>true</alwaysOn>
        <updateRate>15.0</updateRate>
        <cameraName>mobileranger/camera</cameraName>
        <imageTopicName>image_raw</imageTopicName>
        <cameraInfoTopicName>camera_info</cameraInfoTopicName>
        <frameName>left_camera_optical_frame</frameName>
        <!--<rightFrameName>right_camera_optical_frame</rightFrameName>-->
        <hackBaseline>0.07</hackBaseline>
        <distortionK1>0.0</distortionK1>
        <distortionK2>0.0</distortionK2>
        <distortionK3>0.0</distortionK3>
        <distortionT1>0.0</distortionT1>
        <distortionT2>0.0</distortionT2>
      </plugin>
    </sensor>
  </gazebo>
  <link name="imu_link">
    <inertial>
      <mass value="0.001"/>
      <origin rpy="0 0 0" xyz="0 0 0"/>
      <inertia ixx="0.0001" ixy="0" ixz="0" iyy="0.000001" iyz="0" izz="0.0001"/>
    </inertial>
    <visual>
      <origin rpy="0 0 0" xyz="0 0 0"/>
      <geometry>
        <box size="0.1 0.1 0.1"/>
      </geometry>
    </visual>
    <collision>
      <origin rpy="0 0 0" xyz="0 0 0"/>
      <geometry>
        <box size=".001 .001 .001"/>
      </geometry>
    </collision>
  </link>
  <joint name="imu_joint" type="fixed">
    <origin xyz="0 0 0.2"/>
    <parent link="base_link"/>
    <child link="imu_link"/>
  </joint>
  <gazebo>
    <plugin filename="libhector_gazebo_ros_imu.so" name="seekurjr_imu_sim">
      <updateRate>100.0</updateRate>
      <bodyName>base_link</bodyName>
      <topicName>/seekurjr/imu_raw</topicName>
      <rpyOffsets>0 0 0</rpyOffsets>
      <!-- deprecated -->
      <gaussianNoise>0</gaussianNoise>
      <!-- deprecated -->
      <accelDrift>0.5 0.5 0.5</accelDrift>
      <accelGaussianNoise>0.35 0.35 0.3</accelGaussianNoise>
      <rateDrift>0.1 0.1 0.1</rateDrift>
      <rateGaussianNoise>0.05 0.05 0.015</rateGaussianNoise>
      <headingDrift>0.1</headingDrift>
      <headingGaussianNoise>0.05</headingGaussianNoise>
    </plugin>
  </gazebo>
  <!--
  <xacro:include filename="$(find seekurjr_gazebo)/urdf/bumpers.urdf.xml" />
	<xacro:include filename="$(find seekurjr_gazebo)/urdf/bumpers.gazebo.xml" />
	-->
</robot>
