<?xml version="1.0"?>
<robot name="seekurjr" 

       xmlns:xi="http://www.w3.org/2001/XInclude"
       xmlns:gazebo="http://playerstage.sourceforge.net/gazebo/xmlschema/#gz"
       xmlns:model="http://playerstage.sourceforge.net/gazebo/xmlschema/#model"
       xmlns:sensor="http://playerstage.sourceforge.net/gazebo/xmlschema/#sensor"
       xmlns:body="http://playerstage.sourceforge.net/gazebo/xmlschema/#body"
       xmlns:geom="http://playerstage.sourceforge.net/gazebo/xmlschema/#geom"
       xmlns:joint="http://playerstage.sourceforge.net/gazebo/xmlschema/#joint"
       xmlns:interface="http://playerstage.sourceforge.net/gazebo/xmlschema/#interface"
       xmlns:rendering="http://playerstage.sourceforge.net/gazebo/xmlschema/#rendering"
       xmlns:renderable="http://playerstage.sourceforge.net/gazebo/xmlschema/#renderable"
       xmlns:controller="http://playerstage.sourceforge.net/gazebo/xmlschema/#controller"
       xmlns:physics="http://playerstage.sourceforge.net/gazebo/xmlschema/#physics">

  <!-- BASE FOOTPRINT -->
  <!-- base_footprint is a fictitious link(frame) that is on the ground right below base_link origin,
             navigation stack depends on this frame -->
  <link name="base_footprint">
      <inertial>
          <mass value="0.0001" />
          <origin xyz="0 0 0" />
      <inertia ixx="0.0001" ixy="0.0" ixz="0.0"
                         iyy="0.0001" iyz="0.0" 
                         izz="0.0001" />
      </inertial>

      <visual>
          <origin xyz="0 0 0" rpy="0 0 0" />
          <geometry>
             <box size="0.001 0.001 0.001" />
          </geometry>
      </visual>

      <collision>
          <origin xyz="0 0 0.0" rpy="0 0 0" />
          <geometry>
            <box size="0.001 0.001 0.001" />
         </geometry>
     </collision>
  </link>

  <gazebo reference="base_footprint">
    <material>Gazebo/Green</material>
    <turnGravityOff>false</turnGravityOff>
  </gazebo>

  <joint name="base_footprint_joint" type="fixed">
     <!--NB: While you would think this would make it go up, it is oddly reversed.
      This moves the joint to 0,0,0 where we want it for rviz, etc. -->
     <!-- origin xyz="0 0 0.130" rpy="0 0 0" / -->
     <origin xyz="0 0 0.18" rpy="0 0 0" />
     <parent link="base_footprint"/>
     <child link="base_link" />
  </joint>


  <!-- BASE_LINK (RED) -->
  <link name="base_link">
    <inertial>
      <mass value="95.0" />
      <origin xyz="0 0 0" />
      <inertia  ixx="3.737" ixy="0.008"  ixz="-0.144"  iyy="8.311"  iyz="-0.004"  izz="8.893" />
    </inertial>
    <visual>
       <origin xyz="0 0 0" rpy="0 0 0" />
       <geometry>
	 <mesh filename="package://seekurjr_gazebo/meshes/seekurjr_body_new_low.stl"/>
       </geometry>
    </visual>
    <collision>
       <origin xyz="0 0 0.06" rpy="0 0 0 " />
       <geometry>
         <mesh filename="package://seekurjr_gazebo/meshes/seekurjr_body_new_low.stl"/>
	 <!-- box size = "1.0 0.4 0.2"/ -->
       </geometry>
    </collision>     
  </link>
  <gazebo reference="base_link">
    <material>Gazebo/Blue</material>
    <turnGravityOff>false</turnGravityOff>
  </gazebo>


  <!-- BACK LEFT WHEEL (GREY) -->
  <link name="back_left_wheel">
    <inertial>
      <mass value="4.5" />
      <origin xyz="0 0 0" /> 
      <inertia  ixx="0.059" ixy="0.0"  ixz="0.0"  iyy="0.055"  iyz="0.0"  izz="0.059" />
    </inertial>
    <visual>
       <origin xyz="0 0 0" rpy="0 0 3.1416" /> 
       <geometry>
	 <mesh filename="package://seekurjr_gazebo/meshes/seekurjr_wheel_bl.stl"/>
       </geometry>
	<material name="grey">
		<color rgba="0.3 0.3 0.3 1"/>
      	</material>
    </visual>
    <collision>
       <origin xyz="0 0 0" rpy="0 0 0" />
       <geometry>
         <mesh filename="package://seekurjr_gazebo/meshes/seekurjr_wheel_bl.stl"/>
       </geometry>
    </collision>
  </link>
  <gazebo reference="back_left_wheel">
    <mu1 value="10.0"/>
    <mu2 value="0.5"/> 
    <fdir1 value="1 0 0"/>
    <material>Gazebo/Grey</material>
    <turnGravityOff>false</turnGravityOff>
  </gazebo>

  <joint name="joint_back_left_wheel" type="continuous">
    <parent link="base_link"/>
    <child link="back_left_wheel"/>
    <origin xyz="-0.30 0.265 0" rpy="0 0 0" /> 
    <axis xyz="0 1 0" rpy="0 0 0" />
    <limit effort="100" velocity="100"/>
    <joint_properties damping="0.0" friction="0.0"/>
  </joint>




  <!-- BACK RIGHT WHEEL (BLACK) -->
  <link name="back_right_wheel">
    <inertial>
      <mass value="4.5" />
      <origin xyz="0 0 0" />
      <inertia  ixx="0.059" ixy="0.0"  ixz="0.0"  iyy="0.055"  iyz="0.0"  izz="0.059" />
    </inertial>
    <visual>
       <origin xyz="0 0 0" rpy="0 0 0" /> 
       <geometry>
         <mesh filename="package://seekurjr_gazebo/meshes/seekurjr_wheel_br.stl"/>
       </geometry>
	<material name="gray">
		<color rgba="0.3 0.3 0.3 1"/>
      	</material>
    </visual>
    <collision>
       <origin xyz="0 0 0" rpy="0 0 0" /> 
       <geometry>
         <mesh filename="package://seekurjr_gazebo/meshes/seekurjr_wheel_br.stl"/>
       </geometry>
    </collision>
  </link>
  <gazebo reference="back_right_wheel">
    <mu1 value="10.0"/> <!-- 2.0 -->
    <mu2 value="0.5"/> <!-- 0.5 -->
    <fdir1 value="1 0 0"/>
    <material>Gazebo/Grey</material>
    <turnGravityOff>false</turnGravityOff>
  </gazebo>

  <joint name="joint_back_right_wheel" type="continuous">
    <parent link="base_link"/>
    <child link="back_right_wheel"/>
    <origin xyz="-0.30 -0.265 0" rpy="0 0 0" />
    <axis xyz="0 1 0" />
    <limit effort="100" velocity="100"/>
    <joint_properties damping="0.0" friction="0.0"/>
  </joint>



  <!-- FRONT LEFT WHEEL (GREY) -->
  <link name="front_left_wheel">
    <inertial>
      <mass value="4.5" />
      <origin xyz="0 0 0" />
      <inertia  ixx="0.059" ixy="0.0"  ixz="0.0"  iyy="0.055"  iyz="0.0"  izz="0.059" />
    </inertial>
    <visual>
       <origin xyz="0 0 0" rpy="0 0 3.1416" /> 
       <geometry>
         <mesh filename="package://seekurjr_gazebo/meshes/seekurjr_wheel_fl.stl"/>
       </geometry>
	<material name="grey">
		<color rgba="0.3 0.3 0.3 1"/>
      	</material>
    </visual>
    <collision>
       <origin xyz="0 0 0" rpy="0 0 0" /> 
       <geometry>
         <mesh filename="package://seekurjr_gazebo/meshes/seekurjr_wheel_fl.stl"/>
       </geometry>
    </collision>
  </link>
  <gazebo reference="front_left_wheel">
    <mu1 value="10.0"/> <!-- 2.0 -->
    <mu2 value="0.5"/> <!-- 0.5 -->
    <fdir1 value="1 0 0"/>
    <material>Gazebo/Grey</material>
    <turnGravityOff>false</turnGravityOff>
  </gazebo>

  <joint name="joint_front_left_wheel" type="continuous">
    <parent link="base_link"/>
    <child link="front_left_wheel"/>
    <origin xyz="0.30 0.265 0" rpy="0 0 0" />
    <axis xyz="0 1 0" />
    <limit effort="100" velocity="100"/>
    <joint_properties damping="0.0" friction="0.0"/>
  </joint>



  <!-- FRONT RIGHT WHEEL (GREY) -->
  <link name="front_right_wheel">
    <inertial>
      <mass value="4.5" />
      <origin xyz="0 0 0" />
      <inertia  ixx="0.059" ixy="0.0"  ixz="0.0"  iyy="0.055"  iyz="0.0"  izz="0.059" />
    </inertial>
    <visual>
       <origin xyz="0 0 0" rpy="0 0 0" /> 
       <geometry>
         <mesh filename="package://seekurjr_gazebo/meshes/seekurjr_wheel_fr.stl"/>
       </geometry>
	<material name="grey">
		<color rgba="0.3 0.3 0.3 1"/>
      	</material>
    </visual>
    <collision>
       <origin xyz="0 0 0" rpy="0 0 0" /> 
       <geometry>
         <mesh filename="package://seekurjr_gazebo/meshes/seekurjr_wheel_fr.stl"/> 
       </geometry>
    </collision>
  </link>
  <gazebo reference="front_right_wheel">
    <mu1 value="10.0"/> <!-- 2.0 -->
    <mu2 value="0.5"/> <!-- 0.5 -->
    <fdir1 value="1 0 0"/>
    <material>Gazebo/Grey</material>
    <turnGravityOff>false</turnGravityOff>
  </gazebo>

  <joint name="joint_front_right_wheel" type="continuous">
    <parent link="base_link"/>
    <child link="front_right_wheel"/>
    <origin xyz="0.30 -0.265 0" rpy="0 0 0" />
    <axis xyz="0 1 0" />
    <limit effort="100" velocity="100"/>
    <joint_properties damping="0.0" friction="0.0"/>
  </joint>




  <!-- HOKUYO SENSOR -->
  <joint name="hokuyo_laser_joint" type="fixed">
     <axis xyz="0 1 0" />
     <origin xyz="0.12 0 0.285"/>
     <parent link="base_link"/>
     <child link="hokuyo_laser_link"/>
  </joint>
  <link name="hokuyo_laser_link" type="laser">
     <inertial>
       <mass value="0.001" />
       <origin xyz="0 0 0" rpy="0 0 0" />
       <inertia ixx="0.0001" ixy="0" ixz="0" iyy="0.000001" iyz="0" izz="0.0001" />
    </inertial>
    <visual>
      <origin xyz="0 0 0" rpy="0 0 0"/>
      <geometry>
        <!--box size="0.05 0.05 0.1" /-->
	<mesh filename= "package://seekurjr_gazebo/meshes/seekurjr_lms1xx_low.stl" scale="0.5 0.5 0.5"/>
      </geometry>
    </visual>
  </link>

  <!-- This adds a visual box to allow us to see the Hokuyo in rviz/gazebo -->
  <joint name="hokuyo_laser_box_joint" type="fixed">
    <origin xyz="0 0 0" rpy="0 0 0" />
    <parent link="hokuyo_laser_link" />
    <child link="hokuyo_laser_box_link"/>
  </joint>
  <link name="hokuyo_laser_box_link">
    <inertial>
      <mass value="0.01" />
      <origin xyz="0 0 0" />
      <inertia ixx="0.001"  ixy="0.0"  ixz="0.0"
               iyy="0.001"  iyz="0.0"
               izz="0.001" />
    </inertial>

    <collision>
      <origin xyz="0 0 0" rpy="0 0 0"/>
      <geometry>
        <box size="0.05 0.05 0.1" />
      </geometry>
    </collision>
  </link>

  <gazebo reference="hokuyo_laser_box_link">
    <material>Gazebo/FlatBlack</material>
    <turnGravityOff>false</turnGravityOff>
  </gazebo>

  <!-- IMU SENSOR -->

  <joint name="imu_joint" type="fixed">
      <axis xyz="1 0 0"/> <!-- 0 1 0 -->
      <origin xyz="0 0 0.2825"/>
      <parent link="base_link"/>
      <child link="imu_link"/>
  </joint>


  <link name="imu_link">
      <inertial>
        <mass value="0.001"/>
        <origin rpy="0 0 0" xyz="0 0 0"/>
        <inertia ixx="0.0001" ixy="0" ixz="0" iyy="0.000001" iyz="0" izz="0.0001"/>
      </inertial>
      <visual>
        <origin rpy="0 0 0" xyz="0 0 0"/>
        <geometry>
          <box size="0.001 0.001 0.001"/>
        </geometry>
      </visual>
      <collision>
        <origin rpy="0 0 0" xyz="0 0 0"/>
        <geometry>
          <box size=".001 .001 .001"/>
        </geometry>
      </collision>
  </link>

</robot>

